Workbook

Sheet 説明・定義
A1: 就職氷河期世代支援 告知件数 収集テンプレート（狭義・広義 両カウント版）
A3: 対象期間 | B3: 2026年4月10日（高市政権の支援プログラム決定・首相指示）〜 2026年6月30日
A5: 【重要：呼称変更】 | B5: 骨太方針2024を受け、令和7年4月から国の施策は『就職氷河期世代を含む中高年世代（概ね35〜59歳）』へ対象拡大。多くの自治体・労働局がプラットフォームを『中高年活躍応援プロジェクト協議会』へ改組し、『氷河期』の語が表に出ないケースが増加。→ 件数は定義依存。
A6: 狭義カウント | B6: 告知に『就職氷河期（世代）』が明記されているもの。
A7: 広義カウント | B7: 狭義＋『ミドル/中高年/ミドルシニア活躍』等、旧氷河期支援を引き継ぐ告知を含む（狭義を内包＝合計）。
A9: 【告知の定義】 | B9: 就職氷河期/中高年支援に関し、自治体・労働局等が新たに行った周知・募集・案内1件を1カウント。
A10: カウントしない例 | B10: 常設ページの軽微更新、前年度分の再掲、国の全国一律告知（主体区分『国（全国）』で別記録し県別集計に計上しない）。
A12: 【シート】 | B12: ① クロール対象（47県確定URL）→ ② 収集ログ（区分:狭義/広義を選択、告知日を入れると期間内自動判定）→ ③ 集計（県別に狭義件数・広義件数を自動算出）→ ④ 検索クエリ
A14: 【出典】
A15: 起点 | B15: 2026/4/10 関係閣僚会議で新プログラム決定、高市首相が関係閣僚に全力対応を指示
A16: 呼称変更の根拠例 | B16: 京都労働局・大阪府・神奈川県・群馬県の各支援ページ（令和7年4月〜中高年世代へ拡大／協議会へ改組）
A17: 47県公式URL | B17: 北海道庁『47都道府県』リンク集より取得
A18: 注意 | B18: 検索のみでは網羅性・日付確定は保証されない。確定URLを開いて掲載日と対象を確認のこと。

Sheet 集計ルール（定義B）
A1: 集計ルール（定義B：氷河期／中高年に言及する自治体発信すべてを対象）
A3: 対象範囲（定義B） | B3: 就職氷河期世代／中高年（ミドル・ミドルシニア）に言及する都道府県・政令市・労働局・県設置支援センター等の公的発信すべて。セミナー/説明会/相談会に加え、採用試験（氷河期枠）、企画提案公募・委託、企業向け助成金、協議会開催の報道発表を含む。
A4: 狭義／広義 | B4: 狭義＝「就職氷河期（世代）」を明示。広義＝氷河期を含む「中高年/ミドル/ミドルシニア」表記を含む（狭義を包含）。
A5: 告知日の定義 | B5: 機関がその情報を新規／更新として掲載した日（＝掲載日）のみ。開催日・締切日・アラート取得日は告知日にしない。
A6: 開催日（別列） | B6: イベントの実施日は「開催日」列に分離。集計には使わない（掲載日ベースで数える）。
A7: 確度A | B7: 掲載日をページ本体または報道発表で直接確認。→集計に計上。
A8: 確度B | B8: 新着一覧・更新履歴等で掲載日を間接確認。→集計に計上。
A9: 確度C | B9: 掲載日を確認できない（アラート取得日のみ／開催日のみ／常設ページ／要確認）。→告知日は空欄・未計上。別掲「要精査」。
A10: 計上ルール | B10: 確度A・Bのみを集計（期間内フラグ＝告知日が4/10〜6/30内で1）。確度Cは件数に入れず要精査として保持。
A11: 二重計上の回避 | B11: 同一告知が案内する複数イベントは1件。常設ページの通常更新は新規告知としない。
A12: 出所の記録 | B12: 各行に出所（Web巡回／Googleアラート）を記録。手法によるジャンル捕捉の偏りを可視化するため。
A13: 既知のカバレッジ限界 | B13: Web巡回はセミナー系に強く、採用試験・公募・助成の捕捉が弱い。Googleアラートは採用試験系に強い。→両者を統合しても密度は不均一。本集計は「掲載日を確定できた下限」であり、特に採用試験カテゴリは系統的な悉皆調査が未完了。
A14: C2の重要背景 | B14: 地域就職氷河期世代支援加速化交付金は令和6年度で事業終了。令和7年4月1日より内閣府「共生・共助」へ移管（内閣府サイト・令和8年6月1日更新）。よってC2（交付金ベースの企画提案公募）は令和8年度は原則存在せず、青森・兵庫等の県独自/移行事業が例外。C2悉皆は「原則終了＋例外」で締め。
... A17: C1実施県数の主指標 | B17: 「氷河期採用の実施都道府県数」は総務省の悉皆調査（令和6年度実績）を主指標とする＝氷河期限定の中途採用を実施した都道府県は28（実施率59.6%）、受験可能まで広げると46（97.9%）。当方の県別一次確認（R8確定・継続可能性）は令和8年度分の裏取りとして補助的に併記。二次求人サイト（KoumuWIN!/公務in等）は年度が古く件数も不一致のため数値には不採用。

Sheet クロール対象
A1: 都道府県 | B1: 公式サイト（確定） | C1: 県サイト内『就職氷河期』検索 | D1: 県 報道発表/お知らせ 検索 | E1: 管轄労働局・ハローワーク 検索 | F1: 告知ページ確定URL（記入欄） | G1: 備考
A2: 北海道 | B2: https://www.pref.hokkaido.lg.jp/ | C2: site:pref.hokkaido.lg.jp 就職氷河期 | D2: 報道発表内を検索 | E2: 労働局/HWを検索
A3: 青森県 | B3: https://www.pref.aomori.lg.jp/ | C3: site:pref.aomori.lg.jp 就職氷河期 | D3: 報道発表内を検索 | E3: 労働局/HWを検索
A4: 岩手県 | B4: https://www.pref.iwate.jp/ | C4: site:pref.iwate.jp 就職氷河期 | D4: 報道発表内を検索 | E4: 労働局/HWを検索
A5: 宮城県 | B5: https://www.pref.miyagi.jp/ | C5: site:pref.miyagi.jp 就職氷河期 | D5: 報道発表内を検索 | E5: 労働局/HWを検索
A6: 秋田県 | B6: https://www.pref.akita.lg.jp/ | C6: site:pref.akita.lg.jp 就職氷河期 | D6: 報道発表内を検索 | E6: 労働局/HWを検索
A7: 山形県 | B7: https://www.pref.yamagata.jp/ | C7: site:pref.yamagata.jp 就職氷河期 | D7: 報道発表内を検索 | E7: 労働局/HWを検索
A8: 福島県 | B8: https://www.pref.fukushima.lg.jp/ | C8: site:pref.fukushima.lg.jp 就職氷河期 | D8: 報道発表内を検索 | E8: 労働局/HWを検索
A9: 茨城県 | B9: https://www.pref.ibaraki.jp/ | C9: site:pref.ibaraki.jp 就職氷河期 | D9: 報道発表内を検索 | E9: 労働局/HWを検索
A10: 栃木県 | B10: https://www.pref.tochigi.lg.jp/ | C10: site:pref.tochigi.lg.jp 就職氷河期 | D10: 報道発表内を検索 | E10: 労働局/HWを検索
A11: 群馬県 | B11: https://www.pref.gunma.jp/ | C11: site:pref.gunma.jp 就職氷河期 | D11: 報道発表内を検索 | E11: 労働局/HWを検索
A12: 埼玉県 | B12: https://www.pref.saitama.lg.jp/ | C12: site:pref.saitama.lg.jp 就職氷河期 | D12: 報道発表内を検索 | E12: 労働局/HWを検索
A13: 千葉県 | B13: https://www.pref.chiba.lg.jp/ | C13: site:pref.chiba.lg.jp 就職氷河期 | D13: 報道発表内を検索 | E13: 労働局/HWを検索
... A48: 沖縄県 | B48: https://www.pref.okinawa.jp/ | C48: site:pref.okinawa.jp 就職氷河期 | D48: 報道発表内を検索 | E48: 労働局/HWを検索

Sheet 集計B
A1: ビュー1：カテゴリ別 計上件数（確度A/B・期間内のみ）
A2: カテゴリ | B2: 狭義 | C2: 広義(計)
A3: C1採用試験 | B3: =COUNTIFS(収集ログ!$P:$P,$A3,収集ログ!$K:$K,1,収集ログ!$E:$E,"狭義") -> 2 | C3: =COUNTIFS(収集ログ!$P:$P,$A3,収集ログ!$K:$K,1) -> 2
A4: C2公募・委託 | B4: =COUNTIFS(収集ログ!$P:$P,$A4,収集ログ!$K:$K,1,収集ログ!$E:$E,"狭義") -> 0 | C4: =COUNTIFS(収集ログ!$P:$P,$A4,収集ログ!$K:$K,1) -> 0
A5: C3助成 | B5: =COUNTIFS(収集ログ!$P:$P,$A5,収集ログ!$K:$K,1,収集ログ!$E:$E,"狭義") -> 2 | C5: =COUNTIFS(収集ログ!$P:$P,$A5,収集ログ!$K:$K,1) -> 2
A6: C4イベント | B6: =COUNTIFS(収集ログ!$P:$P,$A6,収集ログ!$K:$K,1,収集ログ!$E:$E,"狭義") -> 2 | C6: =COUNTIFS(収集ログ!$P:$P,$A6,収集ログ!$K:$K,1) -> 5
A7: C5訓練 | B7: =COUNTIFS(収集ログ!$P:$P,$A7,収集ログ!$K:$K,1,収集ログ!$E:$E,"狭義") -> 0 | C7: =COUNTIFS(収集ログ!$P:$P,$A7,収集ログ!$K:$K,1) -> 1
A8: C6協議会・制度 | B8: =COUNTIFS(収集ログ!$P:$P,$A8,収集ログ!$K:$K,1,収集ログ!$E:$E,"狭義") -> 0 | C8: =COUNTIFS(収集ログ!$P:$P,$A8,収集ログ!$K:$K,1) -> 0
A9: 合計 | B9: =SUM(B3:B8) -> 6 | C9: =SUM(C3:C8) -> 10
A11: ビュー2：対象軸別 計上件数（確度A/B・期間内）
A12: 対象軸 | B12: 件数
A13: 当事者向け | B13: =COUNTIFS(収集ログ!$Q:$Q,$A13,収集ログ!$K:$K,1) -> 6
A14: 企業向け | B14: =COUNTIFS(収集ログ!$Q:$Q,$A14,収集ログ!$K:$K,1) -> 2
A15: 制度周知 | B15: =COUNTIFS(収集ログ!$Q:$Q,$A15,収集ログ!$K:$K,1) -> 2
A16: 合計 | B16: =SUM(B13:B15) -> 10
A18: ビュー3：確度別・出所別（全期間内候補を含む）
A19: 区分 | B19: 件数 | C19: 説明
A20: 確度A（直接確認） | B20: =COUNTIF(収集ログ!$N:$N,"A") -> 5 | C20: 掲載日をページ/報道発表で確認・計上
A21: 確度B（間接確認） | B21: =COUNTIF(収集ログ!$N:$N,"B") -> 6 | C21: 新着一覧等で確認・計上
A22: 確度C（要精査） | B22: =COUNTIF(収集ログ!$N:$N,"C") -> 84 | C22: 掲載日未確認・未計上
A23: うち出所=アラート | B23: =COUNTIFS(収集ログ!$O:$O,"Googleアラート") -> 7 | C23: 出所内訳（参考）
A24: うち出所=Web巡回 | B24: =COUNTIFS(収集ログ!$O:$O,"Web巡回") -> 88 | C24: 出所内訳（参考）
A25: 計上合計（A+B） | B25: =B20+B21 -> 11 | C25: ← これが定義Bの確定件数（狭義/広義はビュー1参照）
A27: C1採用試験：実施県数（当方の期間内アクティブ確認・補助指標）
A28: 氷河期枠採用試験を実施・期間内に動きを確認した都道府県数 | B28: =COUNTIF(収集ログ!$R:$R,"あり") -> 5 | C28: ※1県1行運用（C1は県ごとに1行に統合）
A30: C1採用試験：実施県数【令和8年度実施・当方一次確認】（補助指標）
A31: 令和8年度に氷河期枠採用を実施している都道府県数 | B31: =COUNTIF(収集ログ!$S:$S,"あり") -> 6 | C31: ※期間内アクティブ(28行)の上位集合。1県1行運用
A32: ＋ 氷河期区分あり・R8未確認（継続可能性） | B32: =COUNTIF(収集ログ!$T:$T,"継続可能性") -> 3 | C32: 令和8年度の一次確認は未了。実施県数には含めない
A33: 【撤回】常設サイトの類型別 県数（維持/改称/併存）
A34: この指標（維持・改称・併存の県数）は、判定を「協議会名の改称」で代用しており、当事者が実際に検索して県の支援ページへ到達できるか（検索到達性）を確認していませんでした。読者の指摘を受けた再検証で神奈川・北海道等が反証されたため、2026-07-05に本指標を撤回。数値は本ファイルの集計・記事の主張には使用しません。詳細は「常設サイト存在マップ（撤回・参考）」シート冒頭を参照。
A40: 【訂正】C1採用試験の「実施都道府県数」について
A41: 当初ここに「氷河期に限定した中途採用を実施＝28都道府県（59.6%）／受験可能46（97.9%）」と記載していたが誤り。「28」は内閣官房PDFのページ番号を実施県数と誤認したもので、一次資料に該当する都道府県数は存在しない（2026-07-06 撤回）。正しい国の一次データは採用者数：①地方公務員の氷河期採用14,299名（令和2〜5年度。うち氷河期限定試験2,199名／氷河期が受験可能な試験12,100名）。②国家公務員 中途採用者選考試験（氷河期）679名（令和2〜5年度・目標600名超過）。③政府方針＝令和8年4月22日「就職氷河期世代の国家公務員中途採用の方針」で令和8〜10年度の継続を決定。実施「県数」の主指標は撤回。当方の全47県一次確認（R8確定6・継続可能性3・確認済不明21）と、上記の国の採用者数・政府方針を根拠とする。出典：内閣官房 就職氷河期世代支援推進室 参考資料（第6回）／総務省採用ページ 20260422方針。

Sheet 常設サイト存在マップ(撤回参考)
A1: ⚠ この分類は撤回しました（2026-07-05）。参考情報としてのみ残しています。
A2: 判定を「協議会名の改称」で代用し、検索到達性を確認していなかったため、記事・集計の主張には使用しません。正しくは「氷河期 支援 ○○県」で県の支援ページに到達できるかで判定すべきで、その再調査は未了です。
A4: （撤回・参考）常設支援サイト・窓口の類型メモ
A6: 都道府県 | B6: 類型 | C6: 根拠（常設サイト・窓口の名称等）
A7: 北海道 | B7: 改称 | C7: 中高年世代活躍応援プロジェクト協議会へ改組
A8: 青森県 | B8: 併存 | C8: 中高年再就職セミナー＋氷河期加速化業務が併存
A9: 岩手県 | B9: 維持 | C9: いわて就職氷河期世代活躍支援PF
A10: 宮城県 | B10: 維持 | C10: 就職氷河期世代支援ページ＋氷河期枠採用試験を維持
A11: 秋田県 | B11: 維持 | C11: あきた就職氷河期世代活躍支援PF／Reチャレンジ秋田
A12: 山形県 | B12: 要確認 | C12: （この巡回では常設サイトの類型を確定できず・要確認）
A13: 福島県 | B13: 併存 | C13: 就職氷河期世代活躍支援＋ミドルエールコーナー
A14: 茨城県 | B14: 要確認 | C14: （この巡回では常設サイトの類型を確定できず・要確認）
A15: 栃木県 | B15: 併存 | C15: 「ミドル世代（就職氷河期世代）」と併記
A16: 群馬県 | B16: 改称 | C16: ぐんま中高年世代活躍応援プロジェクト協議会へ改称
A17: 埼玉県 | B17: 要確認 | C17: （この巡回では常設サイトの類型を確定できず・要確認）
... A53: 沖縄県 | B53: 維持 | C53: 県キャリアセンター 就職氷河期世代支援

Sheet 集計
A1: 起点 | B1: 46122 | D1: ※広義件数＝期間内の全件、狭義件数＝うち『氷河期』明記分。期間は黄色セルで変更可。
A2: 終点 | B2: 46203
A4: 都道府県 | B4: 狭義件数 | C4: 広義件数 | D4: 採用試験 | E4: 相談・支援窓口 | F4: セミナー・説明会・イベント | G4: リスキリング・職業訓練 | H4: 交付金事業周知 | I4: その他
A5: 北海道 | B5: =COUNTIFS(収集ログ!$B:$B,$A5,収集ログ!$E:$E,"狭義",収集ログ!$K:$K,1) -> 0 | C5: =COUNTIFS(収集ログ!$B:$B,$A5,収集ログ!$K:$K,1) -> 0 | D5: =COUNTIFS(収集ログ!$B:$B,$A5,収集ログ!$H:$H,D$4,収集ログ!$K:$K,1) -> 0 | E5: =COUNTIFS(収集ログ!$B:$B,$A5,収集ログ!$H:$H,E$4,収集ログ!$K:$K,1) -> 0 | F5: =COUNTIFS(収集ログ!$B:$B,$A5,収集ログ!$H:$H,F$4,収集ログ!$K:$K,1) -> 0 | G5: =COUNTIFS(収集ログ!$B:$B,$A5,収集ログ!$H:$H,G$4,収集ログ!$K:$K,1) -> 0 | H5: =COUNTIFS(収集ログ!$B:$B,$A5,収集ログ!$H:$H,H$4,収集ログ!$K:$K,1) -> 0 | I5: =COUNTIFS(収集ログ!$B:$B,$A5,収集ログ!$H:$H,I$4,収集ログ!$K:$K,1) -> 0
A6: 青森県 | B6: =COUNTIFS(収集ログ!$B:$B,$A6,収集ログ!$E:$E,"狭義",収集ログ!$K:$K,1) -> 0 | C6: =COUNTIFS(収集ログ!$B:$B,$A6,収集ログ!$K:$K,1) -> 0 | D6: =COUNTIFS(収集ログ!$B:$B,$A6,収集ログ!$H:$H,D$4,収集ログ!$K:$K,1) -> 0 | E6: =COUNTIFS(収集ログ!$B:$B,$A6,収集ログ!$H:$H,E$4,収集ログ!$K:$K,1) -> 0 | F6: =COUNTIFS(収集ログ!$B:$B,$A6,収集ログ!$H:$H,F$4,収集ログ!$K:$K,1) -> 0 | G6: =COUNTIFS(収集ログ!$B:$B,$A6,収集ログ!$H:$H,G$4,収集ログ!$K:$K,1) -> 0 | H6: =COUNTIFS(収集ログ!$B:$B,$A6,収集ログ!$H:$H,H$4,収集ログ!$K:$K,1) -> 0 | I6: =COUNTIFS(収集ログ!$B:$B,$A6,収集ログ!$H:$H,I$4,収集ログ!$K:$K,1) -> 0
A7: 岩手県 | B7: =COUNTIFS(収集ログ!$B:$B,$A7,収集ログ!$E:$E,"狭義",収集ログ!$K:$K,1) -> 0 | C7: =COUNTIFS(収集ログ!$B:$B,$A7,収集ログ!$K:$K,1) -> 0 | D7: =COUNTIFS(収集ログ!$B:$B,$A7,収集ログ!$H:$H,D$4,収集ログ!$K:$K,1) -> 0 | E7: =COUNTIFS(収集ログ!$B:$B,$A7,収集ログ!$H:$H,E$4,収集ログ!$K:$K,1) -> 0 | F7: =COUNTIFS(収集ログ!$B:$B,$A7,収集ログ!$H:$H,F$4,収集ログ!$K:$K,1) -> 0 | G7: =COUNTIFS(収集ログ!$B:$B,$A7,収集ログ!$H:$H,G$4,収集ログ!$K:$K,1) -> 0 | H7: =COUNTIFS(収集ログ!$B:$B,$A7,収集ログ!$H:$H,H$4,収集ログ!$K:$K,1) -> 0 | I7: =COUNTIFS(収集ログ!$B:$B,$A7,収集ログ!$H:$H,I$4,収集ログ!$K:$K,1) -> 0
A8: 宮城県 | B8: =COUNTIFS(収集ログ!$B:$B,$A8,収集ログ!$E:$E,"狭義",収集ログ!$K:$K,1) -> 1 | C8: =COUNTIFS(収集ログ!$B:$B,$A8,収集ログ!$K:$K,1) -> 1 | D8: =COUNTIFS(収集ログ!$B:$B,$A8,収集ログ!$H:$H,D$4,収集ログ!$K:$K,1) -> 0 | E8: =COUNTIFS(収集ログ!$B:$B,$A8,収集ログ!$H:$H,E$4,収集ログ!$K:$K,1) -> 1 | F8: =COUNTIFS(収集ログ!$B:$B,$A8,収集ログ!$H:$H,F$4,収集ログ!$K:$K,1) -> 0 | G8: =COUNTIFS(収集ログ!$B:$B,$A8,収集ログ!$H:$H,G$4,収集ログ!$K:$K,1) -> 0 | H8: =COUNTIFS(収集ログ!$B:$B,$A8,収集ログ!$H:$H,H$4,収集ログ!$K:$K,1) -> 0 | I8: =COUNTIFS(収集ログ!$B:$B,$A8,収集ログ!$H:$H,I$4,収集ログ!$K:$K,1) -> 0
A9: 秋田県 | B9: =COUNTIFS(収集ログ!$B:$B,$A9,収集ログ!$E:$E,"狭義",収集ログ!$K:$K,1) -> 0 | C9: =COUNTIFS(収集ログ!$B:$B,$A9,収集ログ!$K:$K,1) -> 0 | D9: =COUNTIFS(収集ログ!$B:$B,$A9,収集ログ!$H:$H,D$4,収集ログ!$K:$K,1) -> 0 | E9: =COUNTIFS(収集ログ!$B:$B,$A9,収集ログ!$H:$H,E$4,収集ログ!$K:$K,1) -> 0 | F9: =COUNTIFS(収集ログ!$B:$B,$A9,収集ログ!$H:$H,F$4,収集ログ!$K:$K,1) -> 0 | G9: =COUNTIFS(収集ログ!$B:$B,$A9,収集ログ!$H:$H,G$4,収集ログ!$K:$K,1) -> 0 | H9: =COUNTIFS(収集ログ!$B:$B,$A9,収集ログ!$H:$H,H$4,収集ログ!$K:$K,1) -> 0 | I9: =COUNTIFS(収集ログ!$B:$B,$A9,収集ログ!$H:$H,I$4,収集ログ!$K:$K,1) -> 0
A10: 山形県 | B10: =COUNTIFS(収集ログ!$B:$B,$A10,収集ログ!$E:$E,"狭義",収集ログ!$K:$K,1) -> 0 | C10: =COUNTIFS(収集ログ!$B:$B,$A10,収集ログ!$K:$K,1) -> 0 | D10: =COUNTIFS(収集ログ!$B:$B,$A10,収集ログ!$H:$H,D$4,収集ログ!$K:$K,1) -> 0 | E10: =COUNTIFS(収集ログ!$B:$B,$A10,収集ログ!$H:$H,E$4,収集ログ!$K:$K,1) -> 0 | F10: =COUNTIFS(収集ログ!$B:$B,$A10,収集ログ!$H:$H,F$4,収集ログ!$K:$K,1) -> 0 | G10: =COUNTIFS(収集ログ!$B:$B,$A10,収集ログ!$H:$H,G$4,収集ログ!$K:$K,1) -> 0 | H10: =COUNTIFS(収集ログ!$B:$B,$A10,収集ログ!$H:$H,H$4,収集ログ!$K:$K,1) -> 0 | I10: =COUNTIFS(収集ログ!$B:$B,$A10,収集ログ!$H:$H,I$4,収集ログ!$K:$K,1) -> 0
A11: 福島県 | B11: =COUNTIFS(収集ログ!$B:$B,$A11,収集ログ!$E:$E,"狭義",収集ログ!$K:$K,1) -> 0 | C11: =COUNTIFS(収集ログ!$B:$B,$A11,収集ログ!$K:$K,1) -> 0 | D11: =COUNTIFS(収集ログ!$B:$B,$A11,収集ログ!$H:$H,D$4,収集ログ!$K:$K,1) -> 0 | E11: =COUNTIFS(収集ログ!$B:$B,$A11,収集ログ!$H:$H,E$4,収集ログ!$K:$K,1) -> 0 | F11: =COUNTIFS(収集ログ!$B:$B,$A11,収集ログ!$H:$H,F$4,収集ログ!$K:$K,1) -> 0 | G11: =COUNTIFS(収集ログ!$B:$B,$A11,収集ログ!$H:$H,G$4,収集ログ!$K:$K,1) -> 0 | H11: =COUNTIFS(収集ログ!$B:$B,$A11,収集ログ!$H:$H,H$4,収集ログ!$K:$K,1) -> 0 | I11: =COUNTIFS(収集ログ!$B:$B,$A11,収集ログ!$H:$H,I$4,収集ログ!$K:$K,1) -> 0
A12: 茨城県 | B12: =COUNTIFS(収集ログ!$B:$B,$A12,収集ログ!$E:$E,"狭義",収集ログ!$K:$K,1) -> 0 | C12: =COUNTIFS(収集ログ!$B:$B,$A12,収集ログ!$K:$K,1) -> 0 | D12: =COUNTIFS(収集ログ!$B:$B,$A12,収集ログ!$H:$H,D$4,収集ログ!$K:$K,1) -> 0 | E12: =COUNTIFS(収集ログ!$B:$B,$A12,収集ログ!$H:$H,E$4,収集ログ!$K:$K,1) -> 0 | F12: =COUNTIFS(収集ログ!$B:$B,$A12,収集ログ!$H:$H,F$4,収集ログ!$K:$K,1) -> 0 | G12: =COUNTIFS(収集ログ!$B:$B,$A12,収集ログ!$H:$H,G$4,収集ログ!$K:$K,1) -> 0 | H12: =COUNTIFS(収集ログ!$B:$B,$A12,収集ログ!$H:$H,H$4,収集ログ!$K:$K,1) -> 0 | I12: =COUNTIFS(収集ログ!$B:$B,$A12,収集ログ!$H:$H,I$4,収集ログ!$K:$K,1) -> 0
A13: 栃木県 | B13: =COUNTIFS(収集ログ!$B:$B,$A13,収集ログ!$E:$E,"狭義",収集ログ!$K:$K,1) -> 0 | C13: =COUNTIFS(収集ログ!$B:$B,$A13,収集ログ!$K:$K,1) -> 0 | D13: =COUNTIFS(収集ログ!$B:$B,$A13,収集ログ!$H:$H,D$4,収集ログ!$K:$K,1) -> 0 | E13: =COUNTIFS(収集ログ!$B:$B,$A13,収集ログ!$H:$H,E$4,収集ログ!$K:$K,1) -> 0 | F13: =COUNTIFS(収集ログ!$B:$B,$A13,収集ログ!$H:$H,F$4,収集ログ!$K:$K,1) -> 0 | G13: =COUNTIFS(収集ログ!$B:$B,$A13,収集ログ!$H:$H,G$4,収集ログ!$K:$K,1) -> 0 | H13: =COUNTIFS(収集ログ!$B:$B,$A13,収集ログ!$H:$H,H$4,収集ログ!$K:$K,1) -> 0 | I13: =COUNTIFS(収集ログ!$B:$B,$A13,収集ログ!$H:$H,I$4,収集ログ!$K:$K,1) -> 0
A14: 群馬県 | B14: =COUNTIFS(収集ログ!$B:$B,$A14,収集ログ!$E:$E,"狭義",収集ログ!$K:$K,1) -> 0 | C14: =COUNTIFS(収集ログ!$B:$B,$A14,収集ログ!$K:$K,1) -> 0 | D14: =COUNTIFS(収集ログ!$B:$B,$A14,収集ログ!$H:$H,D$4,収集ログ!$K:$K,1) -> 0 | E14: =COUNTIFS(収集ログ!$B:$B,$A14,収集ログ!$H:$H,E$4,収集ログ!$K:$K,1) -> 0 | F14: =COUNTIFS(収集ログ!$B:$B,$A14,収集ログ!$H:$H,F$4,収集ログ!$K:$K,1) -> 0 | G14: =COUNTIFS(収集ログ!$B:$B,$A14,収集ログ!$H:$H,G$4,収集ログ!$K:$K,1) -> 0 | H14: =COUNTIFS(収集ログ!$B:$B,$A14,収集ログ!$H:$H,H$4,収集ログ!$K:$K,1) -> 0 | I14: =COUNTIFS(収集ログ!$B:$B,$A14,収集ログ!$H:$H,I$4,収集ログ!$K:$K,1) -> 0
A15: 埼玉県 | B15: =COUNTIFS(収集ログ!$B:$B,$A15,収集ログ!$E:$E,"狭義",収集ログ!$K:$K,1) -> 0 | C15: =COUNTIFS(収集ログ!$B:$B,$A15,収集ログ!$K:$K,1) -> 1 | D15: =COUNTIFS(収集ログ!$B:$B,$A15,収集ログ!$H:$H,D$4,収集ログ!$K:$K,1) -> 0 | E15: =COUNTIFS(収集ログ!$B:$B,$A15,収集ログ!$H:$H,E$4,収集ログ!$K:$K,1) -> 0 | F15: =COUNTIFS(収集ログ!$B:$B,$A15,収集ログ!$H:$H,F$4,収集ログ!$K:$K,1) -> 1 | G15: =COUNTIFS(収集ログ!$B:$B,$A15,収集ログ!$H:$H,G$4,収集ログ!$K:$K,1) -> 0 | H15: =COUNTIFS(収集ログ!$B:$B,$A15,収集ログ!$H:$H,H$4,収集ログ!$K:$K,1) -> 0 | I15: =COUNTIFS(収集ログ!$B:$B,$A15,収集ログ!$H:$H,I$4,収集ログ!$K:$K,1) -> 0
A16: 千葉県 | B16: =COUNTIFS(収集ログ!$B:$B,$A16,収集ログ!$E:$E,"狭義",収集ログ!$K:$K,1) -> 0 | C16: =COUNTIFS(収集ログ!$B:$B,$A16,収集ログ!$K:$K,1) -> 0 | D16: =COUNTIFS(収集ログ!$B:$B,$A16,収集ログ!$H:$H,D$4,収集ログ!$K:$K,1) -> 0 | E16: =COUNTIFS(収集ログ!$B:$B,$A16,収集ログ!$H:$H,E$4,収集ログ!$K:$K,1) -> 0 | F16: =COUNTIFS(収集ログ!$B:$B,$A16,収集ログ!$H:$H,F$4,収集ログ!$K:$K,1) -> 0 | G16: =COUNTIFS(収集ログ!$B:$B,$A16,収集ログ!$H:$H,G$4,収集ログ!$K:$K,1) -> 0 | H16: =COUNTIFS(収集ログ!$B:$B,$A16,収集ログ!$H:$H,H$4,収集ログ!$K:$K,1) -> 0 | I16: =COUNTIFS(収集ログ!$B:$B,$A16,収集ログ!$H:$H,I$4,収集ログ!$K:$K,1) -> 0
... A51: 沖縄県 | B51: =COUNTIFS(収集ログ!$B:$B,$A51,収集ログ!$E:$E,"狭義",収集ログ!$K:$K,1) -> 0 | C51: =COUNTIFS(収集ログ!$B:$B,$A51,収集ログ!$K:$K,1) -> 0 | D51: =COUNTIFS(収集ログ!$B:$B,$A51,収集ログ!$H:$H,D$4,収集ログ!$K:$K,1) -> 0 | E51: =COUNTIFS(収集ログ!$B:$B,$A51,収集ログ!$H:$H,E$4,収集ログ!$K:$K,1) -> 0 | F51: =COUNTIFS(収集ログ!$B:$B,$A51,収集ログ!$H:$H,F$4,収集ログ!$K:$K,1) -> 0 | G51: =COUNTIFS(収集ログ!$B:$B,$A51,収集ログ!$H:$H,G$4,収集ログ!$K:$K,1) -> 0 | H51: =COUNTIFS(収集ログ!$B:$B,$A51,収集ログ!$H:$H,H$4,収集ログ!$K:$K,1) -> 0 | I51: =COUNTIFS(収集ログ!$B:$B,$A51,収集ログ!$H:$H,I$4,収集ログ!$K:$K,1) -> 0
A52: 全県合計 | B52: =SUM(B5:B51) -> 6 | C52: =SUM(C5:C51) -> 10 | D52: =SUM(D5:D51) -> 2 | E52: =SUM(E5:E51) -> 1 | F52: =SUM(F5:F51) -> 4 | G52: =SUM(G5:G51) -> 1 | H52: =SUM(H5:H51) -> 0 | I52: =SUM(I5:I51) -> 1

Sheet 収集ログ
A1: No | B1: 都道府県 | C1: 主体区分 | D1: 主体名 | E1: 区分 | F1: 告知日 | G1: 告知タイトル | H1: カテゴリ | I1: URL | J1: 確認日 | K1: 期間内 | L1: 備考 | M1: 開催日 | N1: 確度 | O1: 出所 | P1: カテゴリ | Q1: 対象軸 | R1: C1実施(期間内) | S1: C1_R8実施 | T1: C1区分状態
A2: 1 | B2: 埼玉県 | C2: 労働局・ハローワーク | D2: ハローワーク浦和／埼玉しごとセンター | E2: 広義 | F2: 46133 | G2: 5/15開催「ミドル世代就職応援セミナー（求人票の見方・探し方）」 | H2: セミナー・説明会・イベント | I2: https://jsite.mhlw.go.jp/saitama-hellowork/event/index.html | J2: 46185 | K2: =IF($F2="","",IF(AND($F2>=集計!$B$1,$F2<=集計!$B$2),1,0)) -> 1 | L2: 確度:高。ミドル世代＝旧氷河期。掲載日4/21で期間内 | M2: 46157 | N2: B | O2: Web巡回 | P2: C4イベント | Q2: 当事者向け
A3: 2 | B3: 埼玉県 | C3: 政令市・特別区 | D3: さいたま市 | E3: 狭義 | G3: 就職氷河期世代就労支援：マネーライフセミナー＋合同就職面接会 | H3: セミナー・説明会・イベント | I3: https://www.city.saitama.lg.jp/001/005/010/007/index.html | J3: 46185 | K3: =IF($F3="","",IF(AND($F3>=集計!$B$1,$F3<=集計!$B$2),1,0)) | L3: 確度:中。氷河期明記。掲載/開催日を要確認 | N3: C | O3: Web巡回 | P3: C4イベント | Q3: 当事者向け
A4: 3 | B4: 栃木県 | C4: 都道府県 | D4: 栃木県（WORKWORKとちぎ） | E4: 狭義 | G4: ミドル世代（就職氷河期世代）巡回セミナー＆相談会 県北・県南・県央 2026年度 | H4: セミナー・説明会・イベント | I4: https://workwork-tochigi.jp/ | J4: 46185 | K4: =IF($F4="","",IF(AND($F4>=集計!$B$1,$F4<=集計!$B$2),1,0)) | L4: 確度:中。県事業名に氷河期併記。3地区で最大3件。掲載日要確認 | N4: C | O4: Web巡回 | P4: C4イベント | Q4: 当事者向け
A5: 4 | B5: 茨城県 | C5: 労働局・ハローワーク | D5: 茨城労働局（氷河期PF） | E5: 狭義 | G5: キャリアデザインセミナー＋合同企業説明会 | H5: セミナー・説明会・イベント | I5: https://ibaraki-hyogaki.mhlw.go.jp/recruit.html | J5: 46185 | K5: =IF($F5="","",IF(AND($F5>=集計!$B$1,$F5<=集計!$B$2),1,0)) | L5: 確度:低。robotsで自動取得不可。開催日要確認 | N5: C | O5: Web巡回 | P5: C4イベント | Q5: 当事者向け
A6: 5 | B6: 千葉県 | C6: 都道府県 | D6: 千葉県ジョブサポートセンター | E6: 広義 | G6: ミドル世代活躍支援事業 就職支援講座 | H6: セミナー・説明会・イベント | I6: https://www.pref.chiba.lg.jp/koyou/syushokuhyogaki/ | J6: 46185 | K6: =IF($F6="","",IF(AND($F6>=集計!$B$1,$F6<=集計!$B$2),1,0)) | L6: 確度:中。合同説明会は1/30で期間外。在期間内の新規告知を要確認 | N6: C | O6: Web巡回 | P6: C4イベント | Q6: 当事者向け
A7: 6 | B7: 群馬県 | C7: 都道府県 | D7: 群馬県労働政策課 | E7: 広義 | G7: （4/10–6/12の新規告知は未確認） | H7: その他 | I7: https://www.pref.gunma.jp/soshiki/150/index-2.html | J7: 46185 | K7: =IF($F7="","",IF(AND($F7>=集計!$B$1,$F7<=集計!$B$2),1,0)) | L7: 確度:低。PF・専門窓口は2024掲載の常設 | N7: C | O7: Web巡回 | P7: C6協議会・制度 | Q7: 制度周知
A8: 7 | B8: 神奈川県 | C8: 都道府県 | D8: 神奈川県 | E8: 広義 | G8: 「かながわ中高年活躍応援プロジェクト協議会」へ改組（旧氷河期PF） | H8: その他 | I8: https://www.pref.kanagawa.jp/docs/z4r/shushokuhyogaki.html | J8: 46185 | K8: =IF($F8="","",IF(AND($F8>=集計!$B$1,$F8<=集計!$B$2),1,0)) | L8: 確度:低。改組は令和7/5/1で期間外 | N8: C | O8: Web巡回 | P8: C6協議会・制度 | Q8: 制度周知
A9: 8 | B9: 大阪府 | C9: 都道府県 | D9: 大阪府（OSAKAしごとフィールド） | E9: 広義 | G9: 中高年世代活躍応援プロジェクト協議会／ミドル世代就職面接会＆企業説明会 | H9: セミナー・説明会・イベント | I9: https://www.pref.osaka.lg.jp/o110100/koyotaisaku/hyougaki/index.html | J9: 46185 | K9: =IF($F9="","",IF(AND($F9>=集計!$B$1,$F9<=集計!$B$2),1,0)) | L9: 確度:低。面接会は令和7/12/11で期間外。改組済 | N9: C | O9: Web巡回 | P9: C4イベント | Q9: 当事者向け
A10: 9 | B10: 京都府 | C10: 労働局・ハローワーク | D10: 京都労働局 | E10: 広義 | G10: 就職氷河期世代支援特設ページ（令和7年4月に中高年世代へ拡大） | H10: その他 | I10: https://jsite.mhlw.go.jp/kyoto-roudoukyoku/newpage_00331.html | J10: 46185 | K10: =IF($F10="","",IF(AND($F10>=集計!$B$1,$F10<=集計!$B$2),1,0)) | L10: 確度:低。移行・常設。期間内の新規告知を要確認 | N10: C | O10: Web巡回 | P10: C6協議会・制度 | Q10: 制度周知
A11: 10 | B11: 兵庫県 | C11: 都道府県 | D11: 兵庫県 | E11: 狭義 | G11: 令和8年度 就職氷河期世代等就労促進事業 企画提案コンペ参加者募集 | H11: 交付金事業周知 | I11: https://web.pref.hyogo.lg.jp/sr05/hyogaki/hyogopf.html | J11: 46185 | K11: =IF($F11="","",IF(AND($F11>=集計!$B$1,$F11<=集計!$B$2),1,0)) | L11: 確度:中。氷河期明記のR8事業募集。掲載日要確認（期間内の可能性高）／【C2】交付金終了後の県事業。掲載日要精査 | N11: C | O11: Web巡回 | P11: C2公募・委託 | Q11: 制度周知
A12: 11 | B12: 兵庫県 | C12: その他 | D12: 兵庫県就職氷河期世代活躍支援PF | E12: 狭義 | G12: 第6回 就職氷河期世代の雇用セミナー（西宮市民会館） | H12: セミナー・説明会・イベント | I12: https://hyogo-pf.com/ | J12: 46185 | K12: =IF($F12="","",IF(AND($F12>=集計!$B$1,$F12<=集計!$B$2),1,0)) | L12: 確度:中。氷河期明記。開催日要確認 | N12: C | O12: Web巡回 | P12: C4イベント | Q12: 当事者向け
A13: 12 | B13: 滋賀県 | C13: 都道府県 | D13: 滋賀県（シニアジョブステーション滋賀） | E13: 広義 | F13: 46183 | G13: 企業向けセミナー「中高年人材の戦略的活用法」（6/17開催） | H13: セミナー・説明会・イベント | I13: https://www.pref.shiga.lg.jp/kensei/koho/e-shinbun/oshirase/351018.html | J13: 46185 | K13: =IF($F13="","",IF(AND($F13>=集計!$B$1,$F13<=集計!$B$2),1,0)) -> 1 | L13: 確度:高。県eしんぶん6/10掲載で期間内。中高年（広義） | M13: 46190 | N13: B | O13: Web巡回 | P13: C4イベント | Q13: 当事者向け
A14: 13 | B14: 奈良県 | C14: 労働局・ハローワーク | D14: 奈良労働局（中高年世代活躍応援プロジェクト） | E14: 広義 | G14: 中高年世代活躍応援プロジェクト 合同企業説明会等 | H14: セミナー・説明会・イベント | I14: https://chuukounen-nara.mhlw.go.jp/ | J14: 46185 | K14: =IF($F14="","",IF(AND($F14>=集計!$B$1,$F14<=集計!$B$2),1,0)) | L14: 確度:低。掲載イベントは令和7年度(2025)分=期間外。在期間内告知を要確認 | N14: C | O14: Web巡回 | P14: C4イベント | Q14: 当事者向け
A15: 14 | B15: 和歌山県 | C15: 都道府県 | D15: 和歌山県 | E15: 広義 | G15: （4/10–6/12の県固有告知は未確認） | H15: その他 | I15: https://www.pref.wakayama.lg.jp/ | J15: 46185 | K15: =IF($F15="","",IF(AND($F15>=集計!$B$1,$F15<=集計!$B$2),1,0)) | L15: 確度:低。検索で県固有の期間内告知を確認できず。要手動確認 | N15: C | O15: Web巡回 | P15: C6協議会・制度 | Q15: 制度周知
A16: 15 | B16: 愛知県 | C16: 都道府県 | D16: 愛知県（あいち中高年世代活躍応援プロジェクト協議会） | E16: 広義 | G16: あいち合同企業説明会 開催案内 | H16: セミナー・説明会・イベント | I16: https://www.pref.aichi.jp/site/shushokuhyougaki/ | J16: 46185 | K16: =IF($F16="","",IF(AND($F16>=集計!$B$1,$F16<=集計!$B$2),1,0)) | L16: 確度:中。改組(2025/7)。説明会の掲載日を要確認 | N16: C | O16: Web巡回 | P16: C4イベント | Q16: 当事者向け
A17: 16 | B17: 岐阜県 | C17: 都道府県 | D17: 岐阜県（ぎふ中高年世代活躍応援プロジェクト協議会） | E17: 狭義 | G17: 就職氷河期世代向けIT資格取得支援オンライン講座 ほか | H17: リスキリング・職業訓練 | I17: https://www.pref.gifu.lg.jp/page/401403.html | J17: 46185 | K17: =IF($F17="","",IF(AND($F17>=集計!$B$1,$F17<=集計!$B$2),1,0)) | L17: 確度:低。氷河期明記の常設講座。期間内の新規募集告知を要確認 | N17: C | O17: Web巡回 | P17: C5訓練 | Q17: 当事者向け
A18: 17 | B18: 三重県 | C18: 都道府県 | D18: 三重県 | E18: 広義 | G18: （4/10–6/12の県固有告知は未確認） | H18: その他 | I18: https://www.pref.mie.lg.jp/ | J18: 46185 | K18: =IF($F18="","",IF(AND($F18>=集計!$B$1,$F18<=集計!$B$2),1,0)) | L18: 確度:低。検索で県固有の期間内告知を確認できず。要手動確認 | N18: C | O18: Web巡回 | P18: C6協議会・制度 | Q18: 制度周知
A19: 18 | B19: 静岡県 | C19: 労働局・ハローワーク | D19: 静岡労働局（ミドル・チャレンジコーナー） | E19: 広義 | G19: 中高年層（ミドルシニア）専門窓口・各種セミナー | H19: 相談・支援窓口 | I19: https://jsite.mhlw.go.jp/shizuoka-roudoukyoku/roudoukyoku/syokuan/anteika_support.html | J19: 46185 | K19: =IF($F19="","",IF(AND($F19>=集計!$B$1,$F19<=集計!$B$2),1,0)) | L19: 確度:低。常設窓口。期間内の新規セミナー告知を要確認 | N19: C | O19: Web巡回 | P19: C4イベント | Q19: 当事者向け
A20: 19 | B20: 北海道 | C20: 都道府県 | D20: 北海道（雇用労政課） | E20: 狭義 | G20: 就職氷河期世代の活躍のための支援メニュー（5/11ページ更新） | H20: 相談・支援窓口 | I20: https://www.pref.hokkaido.lg.jp/kz/rkr/ss/shuushokuhyougakisien.html | J20: 46185 | K20: =IF($F20="","",IF(AND($F20>=集計!$B$1,$F20<=集計!$B$2),1,0)) | L20: 確度:低。更新日2026/5/11は期間内だが個別告知でなくメニュー更新。要確認 | N20: C | O20: Web巡回 | P20: C4イベント | Q20: 当事者向け
A21: 20 | B21: 青森県 | C21: 都道府県 | D21: 青森県（ネクストキャリアセンターあおもり） | E21: 広義 | G21: 中高年雇用対策（45歳以上）再就職セミナー・合同企業説明会 開催予定 | H21: セミナー・説明会・イベント | I21: https://www.pref.aomori.lg.jp/soshiki/kodomo/wakamono/hatarakizakari-jigyou.html | J21: 46185 | K21: =IF($F21="","",IF(AND($F21>=集計!$B$1,$F21<=集計!$B$2),1,0)) | L21: 確度:低。ページ更新4/1。個別日程はセンターHP掲載=要確認 | N21: C | O21: Web巡回 | P21: C4イベント | Q21: 当事者向け
A22: 21 | B22: 岩手県 | C22: 都道府県 | D22: 岩手県（いわて就職氷河期世代活躍支援PF） | E22: 狭義 | G22: ミドル世代等就職支援事業（就職氷河期世代支援事業） | H22: セミナー・説明会・イベント | I22: https://www.pref.iwate.jp/sangyoukoyou/koyouroudou/koyou/1045189.html | J22: 46185 | K22: =IF($F22="","",IF(AND($F22>=集計!$B$1,$F22<=集計!$B$2),1,0)) | L22: 確度:低。掲載セミナーは過年度実績。期間内の新規告知を要確認 | N22: C | O22: Web巡回 | P22: C4イベント | Q22: 当事者向け
A23: 22 | B23: 宮城県 | C23: 都道府県 | D23: 宮城県（みやぎジョブカフェ等） | E23: 狭義 | F23: 46154 | G23: 就職氷河期世代への就職支援について（交付金活用事業） | H23: 相談・支援窓口 | I23: https://www.pref.miyagi.jp/soshiki/koyou/jobcafe-hyougaki20250207.html | J23: 46185 | K23: =IF($F23="","",IF(AND($F23>=集計!$B$1,$F23<=集計!$B$2),1,0)) -> 1 | L23: 確度:中。県ページ掲載日5/12で期間内。氷河期明記 | N23: B | O23: Web巡回 | P23: C4イベント | Q23: 当事者向け
A24: 23 | B24: 秋田県 | C24: 都道府県 | D24: 秋田県（あきた就職氷河期世代活躍支援PF／Reチャレンジ秋田） | E24: 狭義 | G24: 特設サイトで就職相談会等を告知 | H24: セミナー・説明会・イベント | I24: https://www.pref.akita.lg.jp/pages/genre/56921 | J24: 46185 | K24: =IF($F24="","",IF(AND($F24>=集計!$B$1,$F24<=集計!$B$2),1,0)) | L24: 確度:低。特設サイト常設。期間内の個別告知を要確認 | N24: C | O24: Web巡回 | P24: C4イベント | Q24: 当事者向け
A25: 24 | B25: 山形県 | C25: 労働局・ハローワーク | D25: 山形労働局 | E25: 狭義 | G25: 就職氷河期世代向け短期資格取得コース・職業訓練（氷河期プロジェクト） | H25: リスキリング・職業訓練 | I25: https://jsite.mhlw.go.jp/yamagata-roudoukyoku/hourei_seido_tetsuzuki/hyougaki_00004.html | J25: 46185 | K25: =IF($F25="","",IF(AND($F25>=集計!$B$1,$F25<=集計!$B$2),1,0)) | L25: 確度:低。氷河期明記の訓練案内。期間内の新規募集告知を要確認 | N25: C | O25: Web巡回 | P25: C5訓練 | Q25: 当事者向け
A26: 25 | B26: 福島県 | C26: 都道府県 | D26: 福島県（ミドルエールコーナー等） | E26: 狭義 | G26: 就職氷河期世代活躍支援（各種セミナー・研修） | H26: 相談・支援窓口 | I26: https://www.pref.fukushima.lg.jp/sec/32011c/hyougaki.html | J26: 46185 | K26: =IF($F26="","",IF(AND($F26>=集計!$B$1,$F26<=集計!$B$2),1,0)) | L26: 確度:低。県ページ氷河期明記。期間内の新規セミナー告知を要確認 | N26: C | O26: Web巡回 | P26: C4イベント | Q26: 当事者向け
A27: 26 | B27: 新潟県 | C27: 都道府県 | D27: 新潟県（にいがた就職氷河期世代しごとサポートサイト／労働局委託） | E27: 狭義 | G27: 就職氷河期世代向けセミナー・合同企業説明会（特設サイト） | H27: セミナー・説明会・イベント | I27: https://www.niigata-work.com/events/ | J27: 46185 | K27: =IF($F27="","",IF(AND($F27>=集計!$B$1,$F27<=集計!$B$2),1,0)) | L27: 確度:低。氷河期名を維持。掲載は2-3月中心=要確認。県ページ更新2/19は期間外 | N27: C | O27: Web巡回 | P27: C4イベント | Q27: 当事者向け
A28: 27 | B28: 富山県 | C28: 労働局・ハローワーク | D28: 富山労働局（就職氷河期世代活躍支援PF） | E28: 狭義 | G28: 就職氷河期世代専門相談窓口・参加企業募集 | H28: 相談・支援窓口 | I28: https://www.zinzai-kikaku.jp/toyama-hyogaki/ | J28: 46185 | K28: =IF($F28="","",IF(AND($F28>=集計!$B$1,$F28<=集計!$B$2),1,0)) | L28: 確度:低。氷河期名を維持。常設。期間内の個別告知を要確認 | N28: C | O28: Web巡回 | P28: C4イベント | Q28: 当事者向け
A29: 28 | B29: 石川県 | C29: 都道府県 | D29: 石川県 | E29: 広義 | G29: （4/10–6/12の県固有告知は未確認） | H29: その他 | I29: https://www.pref.ishikawa.lg.jp/ | J29: 46185 | K29: =IF($F29="","",IF(AND($F29>=集計!$B$1,$F29<=集計!$B$2),1,0)) | L29: 確度:低。ジョブカフェ石川は35歳未満中心。要手動確認 | N29: C | O29: Web巡回 | P29: C6協議会・制度 | Q29: 制度周知
A30: 29 | B30: 福井県 | C30: 都道府県 | D30: 福井県 | E30: 狭義 | G30: 中高年世代向けキャリアデザインセミナー＋企業説明会・オンライン交流会 | H30: セミナー・説明会・イベント | I30: https://www.pref.fukui.lg.jp/doc/rousei/kyu-shoku/hyougakishien.html | J30: 46185 | K30: =IF($F30="","",IF(AND($F30>=集計!$B$1,$F30<=集計!$B$2),1,0)) | L30: 確度:低。氷河期ページ内に中高年セミナー告知。開催日を要確認 | N30: C | O30: Web巡回 | P30: C4イベント | Q30: 当事者向け
A31: 30 | B31: 山梨県 | C31: 都道府県 | D31: 山梨県 | E31: 広義 | G31: （4/10–6/12の県固有告知は未確認） | H31: その他 | I31: https://www.pref.yamanashi.jp/ | J31: 46185 | K31: =IF($F31="","",IF(AND($F31>=集計!$B$1,$F31<=集計!$B$2),1,0)) | L31: 確度:低。就業支援センターは能力開発セミナー中心。要手動確認 | N31: C | O31: Web巡回 | P31: C6協議会・制度 | Q31: 制度周知
A32: 31 | B32: 長野県 | C32: 都道府県 | D32: 長野県 | E32: 広義 | G32: （4/10–6/12の県固有告知は未確認） | H32: その他 | I32: https://www.pref.nagano.lg.jp/ | J32: 46185 | K32: =IF($F32="","",IF(AND($F32>=集計!$B$1,$F32<=集計!$B$2),1,0)) | L32: 確度:低。要手動確認 | N32: C | O32: Web巡回 | P32: C6協議会・制度 | Q32: 制度周知
A33: 32 | B33: 鳥取県 | C33: 都道府県 | D33: 鳥取県 | E33: 広義 | G33: （4/10–6/12の県固有告知は未確認） | H33: その他 | I33: https://www.pref.tottori.lg.jp/ | J33: 46185 | K33: =IF($F33="","",IF(AND($F33>=集計!$B$1,$F33<=集計!$B$2),1,0)) | L33: 確度:低。要手動確認 | N33: C | O33: Web巡回 | P33: C6協議会・制度 | Q33: 制度周知
A34: 33 | B34: 島根県 | C34: 都道府県 | D34: 島根県 | E34: 広義 | G34: （4/10–6/12の県固有告知は未確認） | H34: その他 | I34: https://www.pref.shimane.lg.jp/ | J34: 46185 | K34: =IF($F34="","",IF(AND($F34>=集計!$B$1,$F34<=集計!$B$2),1,0)) | L34: 確度:低。県就職支援は学生中心。要手動確認 | N34: C | O34: Web巡回 | P34: C6協議会・制度 | Q34: 制度周知
A35: 34 | B35: 岡山県 | C35: 政令市・特別区 | D35: 岡山市 | E35: 狭義 | G35: 就職氷河期世代（36～51歳）の正規雇用に向けた求職活動支援（個別相談・スキル向上研修） | H35: 相談・支援窓口 | I35: https://www.city.okayama.jp/kurashi/0000036693.html | J35: 46185 | K35: =IF($F35="","",IF(AND($F35>=集計!$B$1,$F35<=集計!$B$2),1,0)) | L35: 確度:低。氷河期明記。掲載日要確認（過年度情報併載） | N35: C | O35: Web巡回 | P35: C4イベント | Q35: 当事者向け
... A41: 40 | B41: 高知県 | C41: 都道府県 | D41: 高知県 | E41: 広義 | G41: （4/10–6/12の県固有告知は未確認） | H41: その他 | I41: https://www.pref.kochi.lg.jp/ | J41: 46185 | K41: =IF($F41="","",IF(AND($F41>=集計!$B$1,$F41<=集計!$B$2),1,0)) | L41: 確度:低。ジョブカフェこうちは学生中心。要手動確認 | N41: C | O41: Web巡回 | P41: C6協議会・制度 | Q41: 制度周知
A42: 41 | B42: 福岡県 | C42: その他 | D42: 福岡県中高年就職支援センター | E42: 狭義 | F42: 46143 | G42: 職種別セミナー・各種就職支援（4/13〜5/1に複数のNEW告知） | H42: セミナー・説明会・イベント | I42: https://www.tsc-f.net/ | J42: 46185 | K42: =IF($F42="","",IF(AND($F42>=集計!$B$1,$F42<=集計!$B$2),1,0)) -> 1 | L42: 確度:中。氷河期明記センター。4/13・4/20・4/23・4/28・5/1にNEW告知が複数（期間内） | N42: B | O42: Web巡回 | P42: C4イベント | Q42: 当事者向け
A43: 42 | B43: 佐賀県 | C43: 都道府県 | D43: 佐賀県 | E43: 広義 | G43: （4/10–6/12の県固有告知は未確認） | H43: その他 | I43: https://www.pref.saga.lg.jp/ | J43: 46185 | K43: =IF($F43="","",IF(AND($F43>=集計!$B$1,$F43<=集計!$B$2),1,0)) | L43: 確度:低。要手動確認 | N43: C | O43: Web巡回 | P43: C6協議会・制度 | Q43: 制度周知
A44: 43 | B44: 長崎県 | C44: 都道府県 | D44: 長崎県（ながさき就職氷河期世代活躍支援PF） | E44: 狭義 | G44: 就職氷河期世代支援サイト（相談窓口・訓練・支援施策の周知） | H44: 相談・支援窓口 | I44: https://www.pref.nagasaki.jp/bunrui/shigoto-sangyo/rodo/hyougaki/ | J44: 46185 | K44: =IF($F44="","",IF(AND($F44>=集計!$B$1,$F44<=集計!$B$2),1,0)) | L44: 確度:低。氷河期名を維持。期間内の新規告知を要確認 | N44: C | O44: Web巡回 | P44: C4イベント | Q44: 当事者向け
A45: 44 | B45: 熊本県 | C45: 都道府県 | D45: 熊本県（くまジョブ） | E45: 狭義 | G45: 就職氷河期世代の就労支援（キャリアカウンセリング等） | H45: 相談・支援窓口 | I45: https://www.pref.kumamoto.jp/soshiki/62/132230.html | J45: 46185 | K45: =IF($F45="","",IF(AND($F45>=集計!$B$1,$F45<=集計!$B$2),1,0)) | L45: 確度:低。氷河期名を維持。期間内の新規告知を要確認 | N45: C | O45: Web巡回 | P45: C4イベント | Q45: 当事者向け
...

Sheet 検索クエリ
A1: 都道府県 | B1: 汎用検索クエリ | C1: 補足チェック先
A2: 北海道 | B2: 北海道 (就職氷河期世代 OR 中高年 OR ミドル) (採用 OR セミナー OR 相談窓口 OR 募集 OR 説明会) 2026 | C2: 北海道公式サイト「報道発表/お知らせ」＋管轄労働局/ハローワークのイベント欄＋県就労支援サイト
A3: 青森県 | B3: 青森県 (就職氷河期世代 OR 中高年 OR ミドル) (採用 OR セミナー OR 相談窓口 OR 募集 OR 説明会) 2026 | C3: 青森県公式サイト「報道発表/お知らせ」＋管轄労働局/ハローワークのイベント欄＋県就労支援サイト
A4: 岩手県 | B4: 岩手県 (就職氷河期世代 OR 中高年 OR ミドル) (採用 OR セミナー OR 相談窓口 OR 募集 OR 説明会) 2026 | C4: 岩手県公式サイト「報道発表/お知らせ」＋管轄労働局/ハローワークのイベント欄＋県就労支援サイト
A5: 宮城県 | B5: 宮城県 (就職氷河期世代 OR 中高年 OR ミドル) (採用 OR セミナー OR 相談窓口 OR 募集 OR 説明会) 2026 | C5: 宮城県公式サイト「報道発表/お知らせ」＋管轄労働局/ハローワークのイベント欄＋県就労支援サイト
A6: 秋田県 | B6: 秋田県 (就職氷河期世代 OR 中高年 OR ミドル) (採用 OR セミナー OR 相談窓口 OR 募集 OR 説明会) 2026 | C6: 秋田県公式サイト「報道発表/お知らせ」＋管轄労働局/ハローワークのイベント欄＋県就労支援サイト
A7: 山形県 | B7: 山形県 (就職氷河期世代 OR 中高年 OR ミドル) (採用 OR セミナー OR 相談窓口 OR 募集 OR 説明会) 2026 | C7: 山形県公式サイト「報道発表/お知らせ」＋管轄労働局/ハローワークのイベント欄＋県就労支援サイト
A8: 福島県 | B8: 福島県 (就職氷河期世代 OR 中高年 OR ミドル) (採用 OR セミナー OR 相談窓口 OR 募集 OR 説明会) 2026 | C8: 福島県公式サイト「報道発表/お知らせ」＋管轄労働局/ハローワークのイベント欄＋県就労支援サイト
A9: 茨城県 | B9: 茨城県 (就職氷河期世代 OR 中高年 OR ミドル) (採用 OR セミナー OR 相談窓口 OR 募集 OR 説明会) 2026 | C9: 茨城県公式サイト「報道発表/お知らせ」＋管轄労働局/ハローワークのイベント欄＋県就労支援サイト
A10: 栃木県 | B10: 栃木県 (就職氷河期世代 OR 中高年 OR ミドル) (採用 OR セミナー OR 相談窓口 OR 募集 OR 説明会) 2026 | C10: 栃木県公式サイト「報道発表/お知らせ」＋管轄労働局/ハローワークのイベント欄＋県就労支援サイト
A11: 群馬県 | B11: 群馬県 (就職氷河期世代 OR 中高年 OR ミドル) (採用 OR セミナー OR 相談窓口 OR 募集 OR 説明会) 2026 | C11: 群馬県公式サイト「報道発表/お知らせ」＋管轄労働局/ハローワークのイベント欄＋県就労支援サイト
A12: 埼玉県 | B12: 埼玉県 (就職氷河期世代 OR 中高年 OR ミドル) (採用 OR セミナー OR 相談窓口 OR 募集 OR 説明会) 2026 | C12: 埼玉県公式サイト「報道発表/お知らせ」＋管轄労働局/ハローワークのイベント欄＋県就労支援サイト
... A48: 沖縄県 | B48: 沖縄県 (就職氷河期世代 OR 中高年 OR ミドル) (採用 OR セミナー OR 相談窓口 OR 募集 OR 説明会) 2026 | C48: 沖縄県公式サイト「報道発表/お知らせ」＋管轄労働局/ハローワークのイベント欄＋県就労支援サイト

Sheet 6-13以降カバレッジ
A1: 6/13〜6/30 追加巡回カバレッジ（地方ブロックごとに機械確認）
A3: 都道府県 | B3: 確認状況 | C3: 結果（6/13–6/30の新規確定告知） | D3: 備考
A4: 北海道 | B4: 確認済 | C4: なし | D4: 改称後/氷河期名の常設窓口・特設サイトが中心
A5: 青森県 | B5: 確認済 | C5: なし | D5: 改称後/氷河期名の常設窓口・特設サイトが中心
A6: 岩手県 | B6: 確認済 | C6: なし | D6: 改称後/氷河期名の常設窓口・特設サイトが中心
A7: 宮城県 | B7: 確認済 | C7: なし（5/12告知内の6/25合同企業説明会＝期間内イベント。既計上のため件数据え置き） | D7: 改称後/氷河期名の常設窓口・特設サイトが中心
A8: 秋田県 | B8: 確認済 | C8: なし | D8: 改称後/氷河期名の常設窓口・特設サイトが中心
A9: 山形県 | B9: 確認済 | C9: なし | D9: 改称後/氷河期名の常設窓口・特設サイトが中心
A10: 福島県 | B10: 確認済 | C10: なし | D10: 改称後/氷河期名の常設窓口・特設サイトが中心
A11: 茨城県 | B11: 確認済 | C11: なし | D11: 常設プログラム/掲載日不明の候補のみ
A12: 栃木県 | B12: 確認済 | C12: あり | D12: 6/22 中高年協議会開催の報道発表（ユーザーGoogleアラート由来・計上）
A13: 群馬県 | B13: 確認済 | C13: なし | D13: 改称後の常設プログラム/掲載日不明の候補のみ（栃木は2026年度巡回セミナー告知あり・個別日未確定）
A14: 埼玉県 | B14: 確認済 | C14: なし | D14: 常設プログラム/掲載日不明の候補のみ
... A50: 沖縄県 | B50: 確認済 | C50: なし | D50: 改称後/氷河期名の常設窓口が中心
A52: ※候補（神奈川6/30 jobフェア・千葉市6月面接会等）は収集ログに記録済み。掲載日確定分のみ集計に計上。
